<?xml version="1.0"?>
<robot name="first_car">

	<!-- Chassis -->
	<link name="chassis">
		<visual>
			<geometry>
				<box size="2.5 1.5 0.8"/>
				<origin rpy="0 0 0" xyz="0 0 0.65"/>
			</geometry>
			<material name="blue">
				<color rgba="0 0 .8 1"/>
			</material>
		</visual>
		<collision>
			<geometry>
				<box size="2.5 1.5 0.8"/>
				<origin rpy="0 0 0" xyz="0 0 0.65"/>
			</geometry>
		</collision>
		<inertial>
			<mass value="10"/>
			<inertia ixx="0.4" ixy="0.0" ixz="0.0" iyy="0.4" iyz="0.0" izz="0.2"/>
		</inertial>
	</link>

	<link name="toit">
		<visual>
			<geometry>
				<box size="1.75 1.5 0.5"/>
				<origin rpy="0 0 0" xyz="-0.3 0 1.3"/>
			</geometry>
			<material name="blue">
				<color rgba="0 0 .8 1"/>
			</material>
		</visual>
		<collision>
			<geometry>
				<box size="1.75 1.5 0.5"/>
				<origin rpy="0 0 0" xyz="-0.3 0 1.3"/>
			</geometry>
		</collision>
		<inertial>
			<mass value="10"/>
			<inertia ixx="0.4" ixy="0.0" ixz="0.0" iyy="0.4" iyz="0.0" izz="0.2"/>
		</inertial>
	</link>

	<!-- Roues -->
	<link name="front_left_wheel">
		<visual>
			<geometry>
				<cylinder length="0.15" radius="0.4"/>
				<origin rpy="1.57075 0 0" xyz="0.75 0.845 0.2"/>
			</geometry>
			<material name="black">
				<color rgba="0 0 0 1"/>
			</material>
		</visual>
		<collision>
			<geometry>
				<cylinder length="0.15" radius="0.4"/>
				<origin rpy="1.57075 0 0" xyz="0.75 0.845 0.2"/>
			</geometry>
		</collision>
		<inertial>
			<mass value="10"/>
			<inertia ixx="0.4" ixy="0.0" ixz="0.0" iyy="0.4" iyz="0.0" izz="0.2"/>
		</inertial>
	</link>

	<link name="front_right_wheel">
		<visual>
			<geometry>
				<cylinder length="0.15" radius="0.4"/>
				<origin rpy="1.57075 0 0" xyz="0.75 -0.845 0.2"/>
			</geometry>
			<material name="black">
				<color rgba="0 0 0 1"/>
			</material>
		</visual>
		<collision>
			<geometry>
				<cylinder length="0.15" radius="0.4"/>
				<origin rpy="1.57075 0 0" xyz="0.75 -0.845 0.2"/>
			</geometry>
		</collision>
		<inertial>
			<mass value="10"/>
			<inertia ixx="0.4" ixy="0.0" ixz="0.0" iyy="0.4" iyz="0.0" izz="0.2"/>
		</inertial>
	</link>

	<link name="rear_left_wheel">
		<visual>
			<geometry>
				<cylinder length="0.15" radius="0.4"/>
				<origin rpy="1.57075 0 0" xyz="-0.75 0.845 0.2"/>
			</geometry>
			<material name="black">
				<color rgba="0 0 0 1"/>
			</material>
		</visual>
		<collision>
			<geometry>
				<cylinder length="0.15" radius="0.4"/>
				<origin rpy="1.57075 0 0" xyz="-0.75 0.845 0.2"/>
			</geometry>
		</collision>
		<inertial>
			<mass value="10"/>
			<inertia ixx="0.4" ixy="0.0" ixz="0.0" iyy="0.4" iyz="0.0" izz="0.2"/>
		</inertial>
	</link>

	<link name="rear_right_wheel">
		<visual>
			<geometry>
				<cylinder length="0.15" radius="0.4"/>
				<origin rpy="1.57075 0 0" xyz="-0.75 0.845 0.2"/>
			</geometry>
			<material name="black">
				<color rgba="0 0 0 1"/>
			</material>
		</visual>
		<collision>
			<geometry>
				<cylinder length="0.15" radius="0.4"/>
				<origin rpy="1.57075 0 0" xyz="-0.75 0.845 0.2"/>
			</geometry>
		</collision>
		<inertial>
			<mass value="10"/>
			<inertia ixx="0.4" ixy="0.0" ixz="0.0" iyy="0.4" iyz="0.0" izz="0.2"/>
		</inertial>
	</link>

	<!-- Mise en place des liens -->

	<joint name="chassis_to_toit" type="fixed">
		<parent link="chassis"/>
		<child link="toit"/>
		<origin xyz="-0.3 0 0.65"/>
	</joint>

	<joint name="chassis_to_front_left_wheel" type="continuous">
		<parent link="chassis"/>
		<child link="front_left_wheel"/>
		<origin rpy="1.57075 0 0" xyz="0.75 0.845 -0.45"/>
		<axis xyz = "0 1 0" />
	</joint>

	<joint name="chassis_to_front_right_wheel" type="continuous">
		<parent link="chassis"/>
		<child link="front_right_wheel"/>
		<origin rpy="1.57075 0 0" xyz="0.75 -0.845 -0.45"/>
		<axis xyz = "0 1 0" />
	</joint>

	<joint name="chassis_to_rear_left_wheel" type="continuous">
		<parent link="chassis"/>
		<child link="rear_left_wheel"/>
		<origin rpy="1.57075 0 0" xyz="-0.75 0.845 -0.45"/>
		<axis xyz = "0 1 0" />
	</joint>

	<joint name="chassis_to_rear_right_wheel" type="continuous">
		<parent link="chassis"/>
		<child link="rear_right_wheel"/>
		<origin rpy="1.57075 0 0" xyz="-0.75 -0.845 -0.45"/>
		<axis xyz = "0 1 0" />
	</joint>

</robot>
