<?xml version="1.0"?>
<robot name="our_car_follower_model">

	<!-- Chassis -->
	<link name="chassis">
		<visual>
			<origin rpy="0 0 0" xyz="0 0 0"/>
			<geometry>
				<box size="2.5 1.5 0.8"/>
			</geometry>
			<material name="blue">
				<color rgba="0.0 0.0 0.8 1.0"/>
			</material>
		</visual>
		<collision>
			<origin rpy="0 0 0" xyz="0 0 0"/>
			<geometry>
				<box size="2.5 1.5 0.8"/>
			</geometry>
		</collision>
		<inertial>
			<mass value="555"/>
			<inertia ixx="0.8" ixy="0.0" ixz="0.0" iyy="5.9" iyz="0.0" izz="5.1"/>
		</inertial>
	</link>

	<link name="toit">
		<visual>
			<origin rpy="0 0 0" xyz="0 0 0"/>
			<geometry>
				<box size="1.75 1.5 0.5"/>
			</geometry>
			<material name="blue">
				<color rgba="0.0 0.0 0.8 1.0"/>
			</material>
		</visual>
		<collision>
			<origin rpy="0 0 0" xyz="0 0 0"/>
			<geometry>
				<box size="1.75 1.5 0.5"/>
			</geometry>
		</collision>
		<inertial>
			<mass value="100"/>
			<inertia ixx="0.4" ixy="0.0" ixz="0.0" iyy="0.4" iyz="0.0" izz="0.2"/>
		</inertial>
	</link>

	<!-- Roues -->
	<link name="front_left_wheel">
		<visual>
			<origin rpy="0 0 0" xyz="0 0 0"/>
			<geometry>
				<cylinder length="0.15" radius="0.4"/>
			</geometry>
		</visual>
		<collision>
			<origin rpy="0 0 0" xyz="0 0 0"/>
			<geometry>
				<cylinder length="0.15" radius="0.4"/>
			</geometry>
			<surface>
        <friction>
          <ode>
            <mu>0.2</mu>
            <mu2>0</mu2>
          </ode>
        </friction>
      </surface>
		</collision>
		<inertial>
			<mass value="10"/>
			<inertia ixx="0.4" ixy="0.0" ixz="0.0" iyy="0.4" iyz="0.0" izz="0.2"/>
		</inertial>
	</link>

	<link name="front_right_wheel">
		<visual>
			<origin rpy="0 0 0" xyz="0 0 0"/>
			<geometry>
				<cylinder length="0.15" radius="0.4"/>
			</geometry>
			<material name="black">
				<color rgba="0.0 0.0 0.0 1.0"/>
			</material>
		</visual>
		<collision>
			<origin rpy="0 0 0" xyz="0 0 0"/>
			<geometry>
				<cylinder length="0.15" radius="0.4"/>
			</geometry>
			<surface>
        <friction>
          <ode>
            <mu>0.2</mu>
            <mu2>0</mu2>
          </ode>
        </friction>
      </surface>
		</collision>
		<inertial>
			<mass value="10"/>
			<inertia ixx="0.4" ixy="0.0" ixz="0.0" iyy="0.4" iyz="0.0" izz="0.2"/>
		</inertial>
	</link>

	<link name="rear_left_wheel">
		<visual>
			<origin rpy="0 0 0" xyz="0 0 0"/>
			<geometry>
				<cylinder length="0.15" radius="0.4"/>
			</geometry>
			<material name="black">
				<color rgba="0.0 0.0 0.0 1.0"/>
			</material>
		</visual>
		<collision>
			<origin rpy="0 0 0" xyz="0 0 0"/>
			<geometry>
				<cylinder length="0.15" radius="0.4"/>
			</geometry>
			<surface>
        <friction>
          <ode>
            <mu>0.2</mu>
            <mu2>0</mu2>
          </ode>
        </friction>
      </surface>
		</collision>
		<inertial>
			<mass value="10"/>
			<inertia ixx="0.4" ixy="0.0" ixz="0.0" iyy="0.4" iyz="0.0" izz="0.2"/>
		</inertial>
	</link>

	<link name="rear_right_wheel">
		<visual>
			<origin rpy="0 0 0" xyz="0 0 0"/>
			<geometry>
				<cylinder length="0.15" radius="0.4"/>
			</geometry>
			<material name="black">
				<color rgba="0.0 0.0 0.0 1.0"/>
			</material>
		</visual>
		<collision>
			<origin rpy="0 0 0" xyz="0 0 0"/>
			<geometry>
				<cylinder length="0.15" radius="0.4"/>
			</geometry>
			<surface>
        <friction>
          <ode>
            <mu>0.2</mu>
            <mu2>0</mu2>
          </ode>
        </friction>
      </surface>
		</collision>
		<inertial>
			<mass value="10"/>
			<inertia ixx="0.4" ixy="0.0" ixz="0.0" iyy="0.4" iyz="0.0" izz="0.2"/>
		</inertial>
	</link>


	<!-- Ajout capteur ultrason -->
	<link name="capteur_ultrason">
    <inertial>
      <mass value="0.001" />
      <origin xyz="0 0 0" rpy="0 0 0" />
      <inertia ixx="0.000000017" ixy="0" ixz="0" iyy="0.000000017" iyz="0" izz="0.000000017" />
    </inertial>
    <collision>
      <origin xyz="0 0 0" rpy="0 0 0" />
      <geometry>
        <box size="0.01 0.01 0.01" />
      </geometry>
    </collision>
    <visual>
      <origin xyz="0 0 0" rpy="0 0 0" />
      <geometry>
        <box size="0.01 0.01 0.01" />
      </geometry>
    </visual>
  </link>

	<gazebo reference="capteur_ultrason">
		<sensor type="ray" name="sensor">
		  <always_on>true</always_on>
		  <update_rate>10</update_rate>
		  <pose>0 0 0 0 0 0</pose>
		  <visualize>true</visualize>
		  <ray>
		    <scan>
		      <horizontal>
		        <samples>16</samples>
		        <resolution>1</resolution>
		        <min_angle>-0.16</min_angle>
		        <max_angle> 0.16</max_angle>
		      </horizontal>
		    </scan>
		    <range>
		      <min>0.05</min>
		      <max>110</max>
		      <resolution>0.02</resolution>
		    </range>
			</ray>
			<plugin name="sonar_controller" filename="libhector_gazebo_ros_sonar.so"/>
		</sensor>
	</gazebo>

<gazebo>
  <plugin name="wheel_controller_follower" filename="libcommande_roues_follower_plugin.so"/>
</gazebo>

	<!-- Mise en place des liens -->

	<joint name="chassis_to_toit" type="fixed">
		<parent link="chassis"/>
		<child link="toit"/>
		<origin xyz="-0.3 0 0.65"/>
	</joint>

	<joint name="chassis_to_front_left_wheel" type="continuous">
		<parent link="chassis"/>
		<child link="front_left_wheel"/>
		<origin rpy="1.57075 0 0" xyz="0.75 0.845 -0.45"/>
		<axis xyz = "0 0 1" />
	</joint>

	<joint name="chassis_to_front_right_wheel" type="continuous">
		<parent link="chassis"/>
		<child link="front_right_wheel"/>
		<origin rpy="1.57075 0 0" xyz="0.75 -0.845 -0.45"/>
		<axis xyz = "0 0 1" />
	</joint>

	<joint name="chassis_to_rear_left_wheel" type="continuous">
		<parent link="chassis"/>
		<child link="rear_left_wheel"/>
		<origin rpy="1.57075 0 0" xyz="-0.75 0.845 -0.45"/>
		<axis xyz = "0 0 1" />
	</joint>

	<joint name="chassis_to_rear_right_wheel" type="continuous">
		<parent link="chassis"/>
		<child link="rear_right_wheel"/>
		<origin rpy="1.57075 0 0" xyz="-0.75 -0.845 -0.45"/>
		<axis xyz = "0 0 1" />
	</joint>

	<joint name="chassis_to_sonar_sensor" type="fixed">
		<parent link="chassis"/>
		<child link="capteur_ultrason"/>
		<origin rpy="0 0 0" xyz="1.25 0 0.41"/>
	</joint>


	<!-- Mise en place des transmissions -->

	<transmission name="front_left_wheel_transmission">
		<type>transmission_interface/SimpleTransmission</type>
		<joint name="chassis_to_front_left_wheel">
			<hardwareInterface>EffortJointInterface</hardwareInterface>
		</joint>
		<actuator name="left_motor"/>
	</transmission>

	<transmission name="front_right_wheel_transmission">
		<type>transmission_interface/SimpleTransmission</type>
		<joint name="chassis_to_front_right_wheel">
			<hardwareInterface>EffortJointInterface</hardwareInterface>
		</joint>
		<actuator name="right_motor"/>
	</transmission>


	<!-- Couleurs -->
	<gazebo reference="front_left_wheel">
		<material>Gazebo/Black</material>
	</gazebo>

	<gazebo reference="front_right_wheel">
		<material>Gazebo/Black</material>
	</gazebo>

	<gazebo reference="rear_left_wheel">
		<material>Gazebo/Black</material>
	</gazebo>

	<gazebo reference="rear_right_wheel">
		<material>Gazebo/Black</material>
	</gazebo>

	<gazebo reference="chassis">
		<material>Gazebo/Orange</material>
	</gazebo>

	<gazebo reference="toit">
		<material>Gazebo/Orange</material>
	</gazebo>



</robot>
