<?xml version="1.0"?>
<robot name="our_car_model_master">

	<!-- Chassis -->
	<link name="chassis">
		<visual>
			<origin rpy="0 0 0" xyz="0 0 0"/>
			<geometry>
				<box size="2.5 1.5 0.8"/>
			</geometry>
			<material name="blue">
				<color rgba="0 0 .8 1"/>
			</material>
		</visual>
		<collision>
			<origin rpy="0 0 0" xyz="0 0 0"/>
			<geometry>
				<box size="2.5 1.5 0.8"/>
			</geometry>
		</collision>
		<inertial>
			<mass value="555"/>
			<inertia ixx="0.8" ixy="0.0" ixz="0.0" iyy="5.9" iyz="0.0" izz="5.1"/>
		</inertial>
	</link>

	<link name="toit">
		<visual>
			<origin rpy="0 0 0" xyz="0 0 0"/>
			<geometry>
				<box size="1.75 1.5 0.5"/>
			</geometry>
			<material name="blue">
				<color rgba="0 0 .8 1"/>
			</material>
		</visual>
		<collision>
			<origin rpy="0 0 0" xyz="0 0 0"/>
			<geometry>
				<box size="1.75 1.5 0.5"/>
			</geometry>
		</collision>
		<inertial>
			<mass value="100"/>
			<inertia ixx="0.4" ixy="0.0" ixz="0.0" iyy="0.4" iyz="0.0" izz="0.2"/>
		</inertial>
	</link>

	<!-- Roues -->
	<link name="front_left_wheel">
		<visual>
			<origin rpy="0 0 0" xyz="0 0 0"/>
			<geometry>
				<cylinder length="0.15" radius="0.4"/>
			</geometry>
			<material name="black">
				<color rgba="0 0 0 1"/>
			</material>
		</visual>
		<collision>
			<origin rpy="0 0 0" xyz="0 0 0"/>
			<geometry>
				<cylinder length="0.15" radius="0.4"/>
			</geometry>
		</collision>
		<inertial>
			<mass value="10"/>
			<inertia ixx="0.4" ixy="0.0" ixz="0.0" iyy="0.4" iyz="0.0" izz="0.2"/>
		</inertial>
	</link>

	<link name="front_right_wheel">
		<visual>
			<origin rpy="0 0 0" xyz="0 0 0"/>
			<geometry>
				<cylinder length="0.15" radius="0.4"/>
			</geometry>
			<material name="black">
				<color rgba="0 0 0 1"/>
			</material>
		</visual>
		<collision>
			<origin rpy="0 0 0" xyz="0 0 0"/>
			<geometry>
				<cylinder length="0.15" radius="0.4"/>
			</geometry>
		</collision>
		<inertial>
			<mass value="10"/>
			<inertia ixx="0.4" ixy="0.0" ixz="0.0" iyy="0.4" iyz="0.0" izz="0.2"/>
		</inertial>
	</link>

	<link name="rear_left_wheel">
		<visual>
			<origin rpy="0 0 0" xyz="0 0 0"/>
			<geometry>
				<cylinder length="0.15" radius="0.4"/>
			</geometry>
			<material name="black">
				<color rgba="0 0 0 1"/>
			</material>
		</visual>
		<collision>
			<origin rpy="0 0 0" xyz="0 0 0"/>
			<geometry>
				<cylinder length="0.15" radius="0.4"/>
			</geometry>
		</collision>
		<inertial>
			<mass value="10"/>
			<inertia ixx="0.4" ixy="0.0" ixz="0.0" iyy="0.4" iyz="0.0" izz="0.2"/>
		</inertial>
	</link>

	<link name="rear_right_wheel">
		<visual>
			<origin rpy="0 0 0" xyz="0 0 0"/>
			<geometry>
				<cylinder length="0.15" radius="0.4"/>
			</geometry>
			<material name="black">
				<color rgba="0 0 0 1"/>
			</material>
		</visual>
		<collision>
			<origin rpy="0 0 0" xyz="0 0 0"/>
			<geometry>
				<cylinder length="0.15" radius="0.4"/>
			</geometry>
		</collision>
		<inertial>
			<mass value="10"/>
			<inertia ixx="0.4" ixy="0.0" ixz="0.0" iyy="0.4" iyz="0.0" izz="0.2"/>
		</inertial>
	</link>

	<gazebo>
	<plugin name="wheel_controller" filename="libcommande_roues_master_plugin.so"/>
	</gazebo>

	<!-- Mise en place des liens -->

	<joint name="chassis_to_toit" type="fixed">
		<parent link="chassis"/>
		<child link="toit"/>
		<origin xyz="-0.3 0 0.65"/>
	</joint>

	<joint name="chassis_to_front_left_wheel" type="continuous">
		<parent link="chassis"/>
		<child link="front_left_wheel"/>
		<origin rpy="1.57075 0 0" xyz="0.75 0.845 -0.45"/>
		<axis xyz = "0 0 1" />
	</joint>

	<joint name="chassis_to_front_right_wheel" type="continuous">
		<parent link="chassis"/>
		<child link="front_right_wheel"/>
		<origin rpy="1.57075 0 0" xyz="0.75 -0.845 -0.45"/>
		<axis xyz = "0 0 1" />
	</joint>

	<joint name="chassis_to_rear_left_wheel" type="continuous">
		<parent link="chassis"/>
		<child link="rear_left_wheel"/>
		<origin rpy="1.57075 0 0" xyz="-0.75 0.845 -0.45"/>
		<axis xyz = "0 0 1" />
	</joint>

	<joint name="chassis_to_rear_right_wheel" type="continuous">
		<parent link="chassis"/>
		<child link="rear_right_wheel"/>
		<origin rpy="1.57075 0 0" xyz="-0.75 -0.845 -0.45"/>
		<axis xyz = "0 0 1" />
	</joint>

</robot>
