<?xml version="1.0"?>
<robot name="our_car_master_model">

  <gazebo>
    <plugin name="wheel_controller_master" filename="libcmdMasterCar.so"/>
  </gazebo>

  <!-- links -->
    <link name="chassis">
      <inertial>
        <mass value="720"/>
        <inertia ixx="140" ixy="0" iyy="550" ixz="0" iyz="0" izz="550"/>
      </inertial>

      <visual name="visual">
        <origin rpy="0 0 -1.570795" xyz="0 0 -0.62"/>
        <geometry>
          <mesh filename="package://car_description/meshes/polaris_ranger.dae" scale="1 1 1"/>
        </geometry>
        <material name="Polaris/Diffuse">
            <texture filename="package://car_description/materials/textures/Ranger_Diffuse.png"/>
        </material>
      </visual>

      <collision name="chassis_bottom">
        <origin rpy="0 0 -1.570795" xyz="0 0 0"/>
        <geometry>
          <box size="1.5 1.34 0.06"/>
        </geometry>
      </collision>

      <collision name="cargo_bottom">
        <origin rpy="0 0 -1.570795" xyz="0 0 0"/>
        <geometry>
          <box size="0.9 1.2 0.01"/>
        </geometry>
      </collision>

      <collision name="cargo_front">
        <origin rpy="0 0 -1.570795" xyz="0 0 0"/>
        <geometry>
          <box size="0.05 1.2 0.25"/>
        </geometry>
      </collision>

      <collision name="cargo_back">
        <origin rpy="0 0 -1.570795" xyz="0 0 0"/>
        <geometry>
          <box size="0.05 1.2 0.25"/>
        </geometry>
      </collision>

      <collision name="cargo_left">
        <origin rpy="0 0 -1.570795" xyz="0 0 0"/>
        <geometry>
          <box size="0.9 0.05 0.25"/>
        </geometry>
      </collision>

      <collision name="cargo_right">
        <origin rpy="0 0 -1.570795" xyz="0 0 0"/>
        <geometry>
          <box size="0.9 0.05 0.25"/>
        </geometry>
      </collision>

      <collision name="seat">
        <origin rpy="0 0 -1.570795" xyz="0 0 0"/>
        <geometry>
          <box size="0.6 1.22 0.5"/>
        </geometry>
      </collision>

      <collision name="mud_seat">
        <origin rpy="0 0 -1.570795" xyz="0 0 0"/>
        <geometry>
          <box size="0.6 1.15 0.1"/>
        </geometry>
      </collision>

      <collision name="seat_back">
        <origin rpy="0 0 -1.570795" xyz="0 0 0"/>
        <geometry>
          <box size="0.06 1 0.4"/>
        </geometry>
      </collision>

      <collision name="engine">
        <origin rpy="0 0 -1.570795" xyz="0 0 0"/>
        <geometry>
          <box size="0.58 1 0.8"/>
        </geometry>
      </collision>

      <collision name="handle_left_middle">
        <origin rpy="0 0 -1.570795" xyz="0 0 0"/>
        <geometry>
          <cylinder radius="0.02" length="0.17"/>
        </geometry>
      </collision>

      <collision name="handle_right_middle">
        <origin rpy="0 0 -1.570795" xyz="0 0 0"/>
        <geometry>
          <cylinder radius="0.02" length="0.17"/>
        </geometry>
      </collision>

      <collision name="rollcage_top_left">
        <origin rpy="0 0 -1.570795" xyz="0 0 0"/>
        <geometry>
          <cylinder radius="0.03" length="0.68"/>
        </geometry>
      </collision>

      <collision name="rollcage_top_right">
        <origin rpy="0 0 -1.570795" xyz="0 0 0"/>
        <geometry>
          <cylinder radius="0.03" length="0.68"/>
        </geometry>
      </collision>

      <collision name="rollcage_top_front">
        <origin rpy="0 0 -1.570795" xyz="0 0 0"/>
        <geometry>
          <cylinder radius="0.03" length="1.22"/>
        </geometry>
      </collision>

      <collision name="rollcage_top_back">
        <origin rpy="0 0 -1.570795" xyz="0 0 0"/>
        <geometry>
          <cylinder radius="0.03" length="1.22"/>
        </geometry>
      </collision>

      <collision name="rollcage_front_left">
        <origin rpy="0 0 -1.570795" xyz="0 0 0"/>
        <geometry>
          <cylinder radius="0.03" length="1.04"/>
        </geometry>
      </collision>

      <collision name="rollcage_front_right">
        <origin rpy="0 0 -1.570795" xyz="0 0 0"/>
        <geometry>
          <cylinder radius="0.03" length="1.04"/>
        </geometry>
      </collision>

      <collision name="fender_front_right">
        <origin rpy="0 0 -1.570795" xyz="0 0 0"/>
        <geometry>
          <cylinder radius="0.03" length="0.72"/>
        </geometry>
      </collision>

      <collision name="fender_front_left">
        <origin rpy="0 0 -1.570795" xyz="0 0 0"/>
        <geometry>
          <cylinder radius="0.03" length="0.72"/>
        </geometry>
      </collision>

      <collision name="rollcage_back_left">
        <origin rpy="0 0 -1.570795" xyz="0 0 0"/>
        <geometry>
          <cylinder radius="0.03" length="0.9"/>
        </geometry>
      </collision>

      <collision name="rollcage_back_right">
        <origin rpy="0 0 -1.570795" xyz="0 0 0"/>
        <geometry>
          <cylinder radius="0.03" length="0.9"/>
        </geometry>
      </collision>

      <collision name="rollcage_back_midleft">
        <origin rpy="0 0 -1.570795" xyz="0 0 0"/>
        <geometry>
          <cylinder radius="0.023" length="0.9"/>
        </geometry>
      </collision>

      <collision name="rollcage_back_midright">
        <origin rpy="0 0 -1.570795" xyz="0 0 0"/>
        <geometry>
          <cylinder radius="0.023" length="0.9"/>
        </geometry>
      </collision>

      <collision name="rollcage_back_upper_left">
        <origin rpy="0 0 -1.570795" xyz="0 0 0"/>
        <geometry>
          <cylinder radius="0.03" length="0.29"/>
        </geometry>
      </collision>

      <collision name="rollcage_back_upper_right">
        <origin rpy="0 0 -1.570795" xyz="0 0 0"/>
        <geometry>
          <cylinder radius="0.03" length="0.29"/>
        </geometry>
      </collision>

      <collision name="rollcage_back_upper_midleft">
        <origin rpy="0 0 -1.570795" xyz="0 0 0"/>
        <geometry>
          <cylinder radius="0.023" length="0.29"/>
        </geometry>
      </collision>

      <collision name="rollcage_back_upper_midright">
        <origin rpy="0 0 -1.570795" xyz="0 0 0"/>
        <geometry>
          <cylinder radius="0.023" length="0.29"/>
        </geometry>
      </collision>
    </link>

<!-- ****************************************************************************** -->

    <link name="rear_right_wheel">
      <inertial>
        <mass value="12"/>
        <inertia ixx="0.5" ixy="0" iyy="0.5" ixz="0" iyz="0" izz="1"/>
      </inertial>

      <collision name="collision">
        <origin rpy="0 0 -1.570795" xyz="0 0 0"/>
        <geometry>
          <cylinder radius="0.32" length="0.23"/>
        </geometry>
      </collision>

      <visual name="visual">
        <origin rpy="0 0 -1.570795" xyz="0 0 -0.62"/>
        <geometry>
          <mesh filename="package://car_description/meshes/polaris_rear_wheel_right.dae" scale="1 1 1"/>
        </geometry>
        <material name="Polaris/Diffuse">
          <texture filename="package://car_description/materials/textures/Ranger_Diffuse.png"/>
        </material>
      </visual>
    </link>

<!-- ****************************************************************************** -->

    <link name="rear_left_wheel">
      <inertial>
        <mass value="12"/>
        <inertia ixx="0.5" ixy="0" iyy="0.5" ixz="0" iyz="0" izz="1"/>
      </inertial>

      <collision name="collision">
        <origin rpy="0 0 -1.570795" xyz="0 0 0"/>
        <geometry>
          <cylinder radius="0.32" length="0.23"/>
        </geometry>
      </collision>

      <visual name="visual">
        <origin rpy="0 0 -1.570795" xyz="0 0 -0.62"/>
        <geometry>
          <mesh filename="package://car_description/meshes/polaris_rear_wheel_left.dae" scale="1 1 1"/>
        </geometry>
        <material name="Polaris/Diffuse">
            <texture filename="package://car_description/materials/textures/Ranger_Diffuse.png"/>
        </material>
      </visual>
    </link>

<!-- ***************************************************************************** -->

    <link name="front_right_wheel">
      <inertial>
        <mass value="12"/>
        <inertia ixx="0.5" ixy="0" iyy="0.5" ixz="0" iyz="0" izz="1"/>
      </inertial>

      <collision name="collision">
        <origin rpy="0 0 -1.570795" xyz="0 0 0"/>
        <geometry>
          <cylinder radius="0.32" length="0.23"/>
        </geometry>
      </collision>

      <visual name="visual">
        <origin rpy="0 0 -1.570795" xyz="0 0 -0.62"/>
        <geometry>
          <mesh filename="package://car_description/meshes/polaris_front_wheel_right.dae" scale="1 1 1"/>
        </geometry>
        <material name="Polaris/Diffuse">
            <texture filename="package://car_description/materials/textures/Ranger_Diffuse.png"/>
        </material>
      </visual>
    </link>

<!-- ***************************************************************************** -->

    <link name="front_right_wheel_steering_block">
      <inertial>
        <mass value="1"/>
        <inertia ixx="1" ixy="0" iyy="1" ixz="0" iyz="0" izz="1"/>
      </inertial>

      <collision name="collision">
        <origin rpy="0 0 -1.570795" xyz="0 0 0"/>
        <geometry>
          <cylinder radius="0.05" length="0.01"/>
        </geometry>
      </collision>
    </link>

<!-- ***************************************************************************** -->

    <link name="front_left_wheel">
      <inertial>
        <mass value="12"/>
        <inertia ixx="0.5" ixy="0" iyy="0.5" ixz="0" iyz="0" izz="1"/>
      </inertial>

      <collision name="collision">
        <origin rpy="0 0 -1.570795" xyz="0 0 0"/>
        <geometry>
          <cylinder radius="0.32" length="0.23"/>
        </geometry>
      </collision>

      <visual name="visual">
        <origin rpy="0 0 -1.570795" xyz="0 0 -0.62"/>
        <geometry>
          <mesh filename="package://car_description/meshes/polaris_front_wheel_left.dae" scale="1 1 1"/>
        </geometry>
        <material name="Polaris/Diffuse">
            <texture filename="package://car_description/materials/textures/Ranger_Diffuse.png"/>
        </material>
      </visual>
    </link>

<!-- ***************************************************************************** -->

    <link name="front_left_wheel_steering_block">
      <inertial>
        <mass value="1"/>
        <inertia ixx="1" ixy="0" iyy="1" ixz="0" iyz="0" izz="1"/>
      </inertial>

      <collision name="collision">
        <origin rpy="0 0 -1.570795" xyz="0 0 0"/>
        <geometry>
          <cylinder radius="0.05" length="0.01"/>
        </geometry>
      </collision>
    </link>

<!-- ***************************************************************************** -->

    <link name="gas_pedal">
      <inertial>
        <mass value="0.1"/>
        <inertia ixx="0.01" ixy="0" ixz="0" iyy="0.01" iyz="0" izz="0.01"/>
      </inertial>

      <collision name="gas_pedal_collision">
        <origin rpy="0 0 -1.570795" xyz="0 0 0"/>
        <geometry>
          <box size="0.1069 0.077 0.01"/>
        </geometry>
      </collision>

      <visual name="visual">
        <origin rpy="0 0 -1.570795" xyz="0 0 -0.62"/>
        <geometry>
          <mesh filename="package://car_description/meshes/polaris_pedal_gas.dae" scale="1 1 1"/>
        </geometry>
        <material name="Polaris/Diffuse">
            <texture filename="package://car_description/materials/textures/Ranger_Diffuse.png"/>
        </material>
      </visual>
    </link>

<!-- ***************************************************************************** -->

    <link name="brake_pedal">
      <inertial>
        <mass value="0.1"/>
        <inertia ixx="0.01" ixy="0" ixz="0" iyy="0.01" iyz="0" izz="0.01"/>
      </inertial>

      <collision name="brake_pedal_collision">
        <origin rpy="0 0 -1.570795" xyz="0 0 0"/>
        <geometry>
          <box size="0.063 0.08 0.01"/>
        </geometry>
      </collision>

      <visual name="visual">
        <origin rpy="0 0 -1.570795" xyz="0 0 -0.62"/>
        <geometry>
          <mesh filename="package://car_description/meshes/polaris_pedal_brake.dae" scale="1 1 1"/>
        </geometry>
        <material name="Polaris/Diffuse">
            <texture filename="package://car_description/materials/textures/Ranger_Diffuse.png"/>
        </material>
      </visual>
    </link>

<!-- ***************************************************************************** -->

    <link name="steering_wheel">
      <inertial>
        <mass value="1"/>
        <inertia ixx="0.012" ixy="0" ixz="0" iyy="0.012" iyz="0" izz="0.024"/>
      </inertial>

      <collision name="collision">
        <origin rpy="0 0 -1.570795" xyz="0 0 0"/>
        <geometry>
          <mesh filename="package://car_description/meshes/polaris_steering_wheel.dae" scale="1 1 1"/>
        </geometry>
      </collision>

      <visual name="visual">
        <origin rpy="0 0 -1.570795" xyz="0 0 -0.62"/>
        <geometry>
          <mesh filename="package://car_description/meshes/polaris_steering_wheel.dae" scale="1 1 1"/>
        </geometry>
        <material name="Polaris/Diffuse">
            <texture filename="package://car_description/materials/textures/Ranger_Diffuse.png"/>
        </material>
      </visual>
    </link>

<!-- ***************************************************************************** -->

    <link name="hand_brake">
      <inertial>
        <mass value="0.5"/>
        <inertia ixx="0.1" ixy="0" ixz="0" iyy="0.1" iyz="0" izz="0.05"/>
      </inertial>

      <collision name="hand_brake_collision">
        <origin rpy="0 0 -1.570795" xyz="0 0 0"/>
        <geometry>
          <mesh filename="package://car_description/meshes/polaris_e_brake.dae"/>
        </geometry>
      </collision>

      <visual name="hand_brake_visual">
        <origin rpy="0 0 -1.570795" xyz="0 0 0"/>
        <geometry>
          <mesh filename="package://car_description/meshes/polaris_e_brake.dae" scale="1 1 1"/>
        </geometry>
        <material name="Polaris/Diffuse">
            <texture filename="package://car_description/materials/textures/Ranger_Diffuse.png"/>
        </material>
      </visual>
    </link>

<!-- ***************************************************************************** -->

    <link name="FNR_switch">
      <inertial>
        <mass value="0.1"/>
        <inertia ixx="0.1" ixy="0" ixz="0" iyy="6e-05" iyz="0" izz="0.1"/>
      </inertial>

      <collision name="FNR_switch">
        <origin rpy="0 0 -1.570795" xyz="0 0 0"/>
        <geometry>
          <box size="0.02 0.04 0.08"/>
        </geometry>
      </collision>

      <visual name="FNR_switch_F">
        <origin rpy="0 0 -1.570795" xyz="0 0 0"/>
        <geometry>
          <box size="0.02 0.04 0.08"/>
        </geometry>
        <material name="FNR_switch_F">
            <texture filename="package://car_description/materials/textures/FNR_switch_F.png"/>
        </material>
      </visual>

      <visual name="FNR_switch_R">
        <origin rpy="0 0 -1.570795" xyz="0 0 0"/>
        <geometry>
          <box size="0.0199 0.0399 0.0799"/>
        </geometry>
        <material name="FNR_switch_R">
            <texture filename="package://car_description/materials/textures/FNR_switch_R.png"/>
        </material>
      </visual>
    </link>

<!-- ***************************************************************************** -->
<!-- ***************************************************************************** -->

<!-- joints -->

    <joint name="front_left_steering_joint" type="continuous">
      <parent link="chassis"/>
      <child link="front_left_wheel_steering_block"/>
      <axis xyz="0 0 1"/>
      <dynamics damping="50"/>
    </joint>

<!-- ***************************************************************************** -->

    <joint name="front_left_wheel_joint" type="continuous">
      <parent link="front_left_wheel_steering_block"/>
      <child link="front_left_wheel"/>
      <axis xyz="0 1 0.05"/>
    </joint>

<!-- ***************************************************************************** -->

    <joint name="front_right_steering_joint" type="continuous">
      <parent link="chassis"/>
      <child link="front_right_wheel_steering_block"/>
      <axis xyz="0 0 1"/>
      <dynamics damping="50"/>
    </joint>

<!-- ***************************************************************************** -->

    <joint name="front_right_wheel_joint" type="continuous">
      <parent link="front_right_wheel_steering_block"/>
      <child link="front_right_wheel"/>
      <axis xyz="0 1 -0.05"/>
    </joint>

<!-- ***************************************************************************** -->

    <joint name="rear_left_wheel_joint" type="continuous">
      <parent link="chassis"/>
      <child link="rear_left_wheel"/>
      <axis xyz="0 1 0.05"/>
    </joint>

<!-- ***************************************************************************** -->

    <joint name="rear_right_wheel_joint" type="continuous">
      <parent link="chassis"/>
      <child link="rear_right_wheel"/>
      <axis xyz="0 1 -0.05"/>
    </joint>

<!-- ***************************************************************************** >

    <joint name="rear_differential_joint" type="continuous">
      <parent link="rear_left_wheel"/>
      <child link="rear_right_wheel"/>
      <axis xyz="0 1 0"/>
      <dynamics damping="70"/>
    </joint>

< ***************************************************************************** -->

    <joint name="gas_joint" type="prismatic">
      <parent link="chassis"/>
      <child link="gas_pedal"/>
      <axis xyz="1 0 -1"/>
      <limit lower="0" upper="0.08" effort="100" velocity="100"/>
      <!-- effort and velocity arbitrarly set -->
      <dynamics damping="3"/>
    </joint>

<!-- ***************************************************************************** -->

    <joint name="brake_joint" type="prismatic">
      <parent link="chassis"/>
      <child link="brake_pedal"/>
      <axis xyz="1 0 -0.6"/>
      <limit lower="0" upper="0.08" effort="100" velocity="100"/>
      <!-- effort and velocity arbitrarly set -->
      <dynamics damping="3"/>
    </joint>

<!-- ***************************************************************************** -->

    <joint name="steering_joint" type="continuous">
      <parent link="chassis"/>
      <child link="steering_wheel"/>
      <axis xyz="-1 0 0.84365"/>
      <dynamics damping="1"/>
    </joint>

<!-- ***************************************************************************** -->

    <joint name="hand_brake_joint" type="revolute">
      <parent link="chassis"/>
      <child link="hand_brake"/>
      <axis xyz="0 -1 0"/>
      <limit lower="0" upper="0.6" effort="50" velocity="50"/>
      <!-- effort and velocity arbitrarly set -->
      <dynamics damping="1"/>
    </joint>

<!-- ***************************************************************************** -->

    <joint name="FNR_switch_joint" type="revolute">
      <parent link="chassis"/>
      <child link="FNR_switch"/>
      <axis xyz="0 -1 0"/>
      <limit lower="-0.3" upper="0.3" effort="50" velocity="50"/>
      <!-- effort and velocity arbitrarly set -->
      <dynamics damping="0.01"/>
    </joint>

<!-- FIN -->
</robot>
